Workbook

Sheet COPERTINA
N6: Seainnova Boe per L'ormeggio – Business Plan 2027–2032
N10: Versione ricalcolata e verificata – Gennaio 2027
N13: Soluzioni Blue IoT per ormeggi e infrastrutture portuali intelligenti
N20: 🔴 VERSIONE 3.0 - Tier 2 - Pronta per investitori
N22: 🔴 v3.0 — Correzioni di solidità finanziaria
N23: • Sconto fornitore 30% RIMOSSO → CAPEX boe 6,01M€ → 8,58M€
N24: • PNRR ammissibile riallineato → contributo 560k → 200k
N25: • ZES esplicitato (cap 256k, max teorico 70% CAPEX boe)
N26: • Distinzione cassa vs credito imposta in compensazione

Sheet INDICE
A2: Business Plan Seainnova
B4: INDICE DI NAVIGAZIONE
B6: INPUT & ASSUNZIONI
C7: Leggenda
C8: Assunzioni
C9: Glossario
B11: ANALISI OPERATIVA
A12: Bp 2027 2032
A13: NaviGoo24
B15: REPORTISTICA FINANZIARIA
C16: Conto_Economico
C17: Piano_Finanziario
B19: VISUALIZZAZIONE & DASHBOARD
C20: DASHBOARD
A21: Grafici NaviGoo24
B23: ANALISI DI RESILIENZA | C23: ANALISI BEP

Sheet RELAZIONE
B1: Relazione di accompagnamento al Business Plan
B3: Seainnova S.r.l. — Boe per l'Ormeggio Intelligenti
B4: Piano Economico-Finanziario 2027–2032 · Versione 3.0
B6: ──────────────────────────────────────────────────────────────────────────────────────────
B8: 1. Sintesi esecutiva
B10: Seainnova S.r.l., start-up innovativa con sede a La Maddalena (Sardegna), presenta il piano economico-finanziario per il periodo 2027–2032 relativo allo sviluppo, produzione e commercializzazione di un sistema integrato di **boe da ormeggio intelligenti** (linea Betty Buoys) abbinato a una piattaforma software B2B (NaviGoo24 / PUCK) per la gestione digitale degli ormeggi.
B12: **Numeri chiave del piano consolidato (Boe + PUCK B2B):**
B14: | Indicatore | 2027 | 2032 | Cumulato 6 anni |
B15: |---|---:|---:|---:|
B16: | Boe operative | 15 | 715 | — |
B17: | Ricavi totali | 187 k€ | 6.599 k€ | **16.815 k€** |
B18: | EBITDA totale | -4 k€ | 5.241 k€ | **12.844 k€** |
... B247: **Riferimenti:** Seainnova S.r.l. — Luca Rovere (CEO) — luca.rovere@seainnova.com — La Maddalena (SS)

Sheet Leggenda
B2: 📖 GUIDA ALL'USO DEL BUSINESS PLAN
B3: Seainnova - Sistema Boe Ormeggio Intelligenti 2027-2032
B6: 📊 STRUTTURA DEL BUSINESS PLAN
B7: Foglio | C7: Descrizione | D7: Tipo
B8: 1. Leggenda | C8: Questa pagina - Guida all'uso | D8: Informativa
B9: 2. Assunzioni | C9: ⚙️ PARAMETRI INPUT - Modifica qui tutti i valori | D9: EDITABILE ✏️
B10: 3. BP_BettyBuoys_2027_2032 | C10: Piano completo 6 anni con formule automatiche | D10: Calcolato 🔄
B11: 4. DASHBOARD | C11: Sintesi visiva e KPI principali | D11: Calcolato 🔄
B12: 5. Conto_Economico | C12: Dettaglio ricavi, costi, EBITDA anno per anno | D12: Calcolato 🔄
B13: 6. Glossario | C13: Definizioni termini tecnici e finanziari | D13: Informativa
B16: 🎨 CODICE COLORI CELLE
B17: Colore | C17: Significato | D17: Azione
B18: Grigio chiaro | C18: Cella INPUT - Valore che puoi modificare | D18: ✏️ MODIFICA LIBERAMENTE
B19: Giallo chiaro | C19: Cella FORMULA - Si aggiorna automaticamente | D19: 🔒 NON MODIFICARE
B20: Blu scuro | C20: HEADER - Intestazione colonna/sezione | D20: 🔒 NON MODIFICARE
B21: Arancione | C21: TOTALE - Somma o aggregazione | D21: 🔒 NON MODIFICARE
B24: ⚙️ COME MODIFICARE IL BUSINESS PLAN
B25: Step | C25: Azione | D25: Note
B26: 1 | C26: Vai al foglio 'Assunzioni' | D26: Qui trovi TUTTI i parametri modificabili
B27: 2 | C27: Identifica le celle GRIGIE | D27: Solo queste sono editabili
B28: 3 | C28: Modifica il valore desiderato | D28: Esempio: cambia boe da 15 a 20
B29: 4 | C29: Premi INVIO | D29: Tutte le formule si aggiornano automaticamente
B30: 5 | C30: Verifica i risultati | D30: Controlla DASHBOARD o BP per vedere l'impatto
B33: 📋 PARAMETRI PRINCIPALI MODIFICABILI
B34: Parametro | C34: Dove Trovarlo | D34: Impatto
B35: Boe nuove per anno | C35: Assunzioni → C8:C13 | D35: Deployment, ricavi, costi
B36: Tariffa €/uso | C36: Assunzioni → C17:C22 | D36: Ricavi totali
B37: Occupancy % | C37: Assunzioni → D17:D22 | D37: Ricavi totali, utilizzo
B38: Costo boa | C38: Assunzioni → C26 | D38: Costi diretti produzione
B39: OPEX base | C39: Assunzioni → C27 | D39: Costi operativi
B40: Crescita OPEX | C40: Assunzioni → C28 | D40: Aumento costi anno su anno
B41: Incentivi PNRR/ZES | C41: Assunzioni → C34:C36 | D41: Riduzione costi effettivi
B44: 📚 GLOSSARIO TERMINI FINANZIARI
B45: Termine | C45: Definizione Semplice
B46: CAPEX | C46: Investimenti in beni (boe, hardware) - spesa una tantum
B47: OPEX | C47: Costi operativi ricorrenti (stipendi, manutenzione) - ogni anno
B48: EBITDA | C48: Utile operativo = Ricavi - OPEX - Costi diretti
B49: Margine % | C49: Percentuale di guadagno sui ricavi = EBITDA / Ricavi
B50: Break-even | C50: Punto dove ricavi = costi (né guadagno né perdita)
B51: Occupancy | C51: % utilizzo delle boe = giorni occupati / giorni disponibili
...

Sheet Assunzioni
B2: ⚙️ PARAMETRI E ASSUNZIONI - Seainnova
B3: Modifica questi valori per aggiornare tutto il Business Plan
B4: 🟡 LEGENDA RISCHI: i banner gialli evidenziano ipotesi soggette a verifica esterna (bandi, istruttorie, trattative fornitori). Numeri indicativi, non garantiti.
B6: 📍 DEPLOYMENT BOE (EDITABILE)
B7: Anno | C7: Boe Nuove | D7: Note
B8: 2027 | C8: 15 | D8: Pilot - validazione
B9: 2028 | C9: 60 | D9: Prima espansione
B10: 2029 | C10: 100 | D10: Scalata
B11: 2030 | C11: 140 | D11: Consolidamento
B12: 2031 | C12: 180 | D12: Espansione massiva
B13: 2032 | C13: 220 | D13: Completamento
B15: 💰 PREZZI E OCCUPANCY (EDITABILE)
B16: Anno | C16: Tariffa €/uso | D16: Occupancy % | E16: Giorni op./anno
B17: 2027 | C17: 92 | D17: 60 | E17: 150
B18: 2028 | C18: 60 | D18: 80 | E18: 180
B19: 2029 | C19: 52 | D19: 90 | E19: 180
B20: 2030 | C20: 50 | D20: 95 | E20: 180
B21: 2031 | C21: 50 | D21: 95 | E21: 180
B22: 2032 | C22: 50 | D22: 95 | E22: 180
B24: 💸 COSTI UNITARI (EDITABILE)
B25: Voce | C25: Valore | D25: Unità | E25: Note
B26: Costo boa completa | C26: 12000 | D26: €/boa | E26: Costo a listino pieno (sconto volume azzerato in v3.0)
B27: OPEX base anno 1 | C27: 70000 | D27: €/anno | E27: Personale + APP + logistica + utilities (dettaglio PDF 2022)
B28: Crescita OPEX annua | C28: 5 | D28: % | E28: Incremento costi operativi
B29: CAPEX base anno | C29: 50000 | D29: € | E29: Investimenti fissi annui
B30: CAPEX per boa nuova | C30: 0 | D30: €/boa | E30: Costo aggiuntivo per ogni boa
B32: 🎁 INCENTIVI FISCALI (EDITABILE)
B33: Incentivo | C33: Percentuale % | D33: Note
B34: PNRR copertura | C34: 80 | D34: Copertura costi investimento
B35: ZES credito imposta | C35: 70 | D35: Credito fiscale Sardegna
B36: Sconto applicato costi | C36: 0 | D36: Sconto rimosso (prudenza valutativa) - vedi v3.0
B38: ℹ️ NOTA SCONTO BOE — In v3.0 azzerato (prudenza valutativa)
B39: Costo boa fissato a listino pieno 12.000€. Eventuale sconto volume può essere reintrodotto in cella C36 (es. 15-20%) solo dopo trattativa formalizzata con fornitore primario. Effetto: ogni 10 punti di sconto ≈ -858k€ di CAPEX boe sui 6 anni.
B40: 💸 COSTI RICORRENTI PER BOA (EDITABILE)
B41: Voce | C41: Valore | D41: Unità | E41: Note
B42: Ricambi garanzia | C42: 312 | D42: €/boa/anno | E42: Manutenzione preventiva
B43: Assicurazione | C43: 65 | D43: €/boa/anno | E43: Copertura RC e danni
B44: SIM dati | C44: 48 | D44: €/boa/anno | E44: 4€/mese × 12 mesi
B45: Posa/smontaggio stagionale | C45: 1125 | D45: €/boa/anno | E45: Installazione inizio/fine stagione
B46: TOTALE per boa/anno | C46: =SUM(C42:C45) | D46: €/boa/anno | E46: Moltiplicare per numero boe cumulative
...

Sheet BP_Seainnova 2027_2032
A2: BUSINESS PLAN COMPLETO 2027-2032
A3: 📊 Valori calcolati automaticamente da foglio Assunzioni
A4: Anno | B4: Boe Nuove | C4: Boe Cumul. | D4: Tariffa € | E4: Occ % | F4: Gg/anno | G4: Ormeggi/anno | H4: Ricavi € | I4: CAPEX Boe € | J4: OPEX € | K4: Ammortam. € | L4: EBITDA € | M4: EBIT € | N4: NaviGoo24 Ricavi € | O4: NaviGoo24 OPEX € | P4: EBITDA NavoGoo24 | Q4: Ricavi TOTALI € | R4: Costi Tot. € | S4: CAPEX Tot. € | T4: EBITDA Tot. €
A5: Anno | B5: Boe Nuove | C5: Boe Cumulative | D5: Tariffa Giorno | E5: Occupancy % | F5: Giorni Operativi | G5: Ormeggi Anno | H5: Ricavi | I5: CAPEX Boe | J5: OPEX | K5: Ammortamenti | L5: EBITDA | M5: EBIT | N5: Ricavi PUCk B2B | O5: OPEX PUCk B2B | P5: EBITDA | Q5: Ricavi Totali | R5: Costi Totali | S5: CAPEX Totale | T5: EBITDA Totale
A6: 2027 | B6: =Assunzioni!C8 | C6: =B6 | D6: =Assunzioni!C17 | E6: =Assunzioni!D17/100 | F6: =Assunzioni!E17 | G6: =C6*E6*F6 | H6: =G6*D6 | I6: =B6*Assunzioni!$C$26*(1-Assunzioni!$C$36/100) | J6: =Assunzioni!$C$27*(1+Assunzioni!$C$28/100)^0 + Assunzioni!$C$46*C6 | K6: =Assunzioni!$D$115 | L6: =H6-J6 | M6: =L6-K6 | N6: =(Assunzioni!D129*Assunzioni!C123+Assunzioni!E129*Assunzioni!C124+Assunzioni!F129*Assunzioni!C125)*12 | O6: =Assunzioni!C137+Assunzioni!D137+Assunzioni!E137+Assunzioni!F137 | P6: =N6-O6 | Q6: =H6+N6 | R6: =J6+O6 | S6: =I6+Assunzioni!H51 | T6: =Q6-R6
A7: 2028 | B7: =Assunzioni!C9 | C7: =C6+B7 | D7: =Assunzioni!C18 | E7: =Assunzioni!D18/100 | F7: =Assunzioni!E18 | G7: =C7*E7*F7 | H7: =G7*D7 | I7: =B7*Assunzioni!$C$26*(1-Assunzioni!$C$36/100) | J7: =Assunzioni!$C$27*(1+Assunzioni!$C$28/100)^1 + Assunzioni!$C$46*C7 | K7: =Assunzioni!$E$115 | L7: =H7-J7 | M7: =L7-K7 | N7: =(Assunzioni!D130*Assunzioni!$C$123+Assunzioni!E130*Assunzioni!$C$124+Assunzioni!F130*Assunzioni!$C$125)*12 | O7: =Assunzioni!C138+Assunzioni!D138+Assunzioni!E138+Assunzioni!F138 | P7: =N7-O7 | Q7: =H7+N7 | R7: =J7+O7 | S7: =I7+Assunzioni!H52 | T7: =Q7-R7
A8: 2029 | B8: =Assunzioni!C10 | C8: =C7+B8 | D8: =Assunzioni!C19 | E8: =Assunzioni!D19/100 | F8: =Assunzioni!E19 | G8: =C8*E8*F8 | H8: =G8*D8 | I8: =B8*Assunzioni!$C$26*(1-Assunzioni!$C$36/100) | J8: =Assunzioni!$C$27*(1+Assunzioni!$C$28/100)^2 + Assunzioni!$C$46*C8 | K8: =Assunzioni!$F$115 | L8: =H8-J8 | M8: =L8-K8 | N8: =(Assunzioni!D131*Assunzioni!$C$123+Assunzioni!E131*Assunzioni!$C$124+Assunzioni!F131*Assunzioni!$C$125)*12 | O8: =Assunzioni!C139+Assunzioni!D139+Assunzioni!E139+Assunzioni!F139 | P8: =N8-O8 | Q8: =H8+N8 | R8: =J8+O8 | S8: =I8+Assunzioni!H53 | T8: =Q8-R8
A9: 2030 | B9: =Assunzioni!C11 | C9: =C8+B9 | D9: =Assunzioni!C20 | E9: =Assunzioni!D20/100 | F9: =Assunzioni!E20 | G9: =C9*E9*F9 | H9: =G9*D9 | I9: =B9*Assunzioni!$C$26*(1-Assunzioni!$C$36/100) | J9: =Assunzioni!$C$27*(1+Assunzioni!$C$28/100)^3 + Assunzioni!$C$46*C9 | K9: =Assunzioni!$G$115 | L9: =H9-J9 | M9: =L9-K9 | N9: =(Assunzioni!D132*Assunzioni!$C$123+Assunzioni!E132*Assunzioni!$C$124+Assunzioni!F132*Assunzioni!$C$125)*12 | O9: =Assunzioni!C140+Assunzioni!D140+Assunzioni!E140+Assunzioni!F140 | P9: =N9-O9 | Q9: =H9+N9 | R9: =J9+O9 | S9: =I9+Assunzioni!H54 | T9: =Q9-R9
A10: 2031 | B10: =Assunzioni!C12 | C10: =C9+B10 | D10: =Assunzioni!C21 | E10: =Assunzioni!D21/100 | F10: =Assunzioni!E21 | G10: =C10*E10*F10 | H10: =G10*D10 | I10: =B10*Assunzioni!$C$26*(1-Assunzioni!$C$36/100) | J10: =Assunzioni!$C$27*(1+Assunzioni!$C$28/100)^4 + Assunzioni!$C$46*C10 | K10: =Assunzioni!$H$115 | L10: =H10-J10 | M10: =L10-K10 | N10: =(Assunzioni!D133*Assunzioni!$C$123+Assunzioni!E133*Assunzioni!$C$124+Assunzioni!F133*Assunzioni!$C$125)*12 | O10: =Assunzioni!C141+Assunzioni!D141+Assunzioni!E141+Assunzioni!F141 | P10: =N10-O10 | Q10: =H10+N10 | R10: =J10+O10 | S10: =I10+Assunzioni!H55 | T10: =Q10-R10
A11: 2032 | B11: =Assunzioni!C13 | C11: =C10+B11 | D11: =Assunzioni!C22 | E11: =Assunzioni!D22/100 | F11: =Assunzioni!E22 | G11: =C11*E11*F11 | H11: =G11*D11 | I11: =B11*Assunzioni!$C$26*(1-Assunzioni!$C$36/100) | J11: =Assunzioni!$C$27*(1+Assunzioni!$C$28/100)^5 + Assunzioni!$C$46*C11 | K11: =Assunzioni!$I$115 | L11: =H11-J11 | M11: =L11-K11 | N11: =(Assunzioni!D134*Assunzioni!$C$123+Assunzioni!E134*Assunzioni!$C$124+Assunzioni!F134*Assunzioni!$C$125)*12 | O11: =Assunzioni!C142+Assunzioni!D142+Assunzioni!E142+Assunzioni!F142 | P11: =N11-O11 | Q11: =H11+N11 | R11: =J11+O11 | S11: =I11+Assunzioni!H56 | T11: =Q11-R11
A12: TOTALE | B12: =SUM(B6:B11) | C12: =C11 | E12: =AVERAGE(E6:E11) | G12: =SUM(G6:G11) | H12: =SUM(H6:H11) | I12: =SUM(I6:I11) | J12: =SUM(J6:J11) | K12: =SUM(K6:K11) | L12: =SUM(L6:L11) | M12: =SUM(M6:M11) | N12: =SUM(N6:N11) | ... S12: =SUM(S6:S11) | T12: =Q12-R12
C33: Percentuale %

Sheet DASHBOARD
B2: BUSINESS PLAN SEAINNOVA 2027-2032
B3: 📈 Dashboard aggiornata automaticamente
B5: 📊 HIGHLIGHTS PERIODO
B6: Ricavi 6 anni | C6: ='BP_Seainnova 2027_2032'!H12/1000000 | D6: M€
B7: EBITDA 6 anni | C7: ='BP_Seainnova 2027_2032'!L12/1000000 | D7: M€
B8: CAPEX totale 6 anni | C8: ='BP_Seainnova 2027_2032'!S12/1000000 | D8: M€
B9: Margine EBITDA medio | C9: =IF('BP_Seainnova 2027_2032'!H12=0,0,'BP_Seainnova 2027_2032'!L12/'BP_Seainnova 2027_2032'!H12) | D9: %
B10: Boe totali fine periodo | C10: ='BP_Seainnova 2027_2032'!C11 | D10: unità
B11: Break-even | C11: Anno 3 (2029)
B12: EBIT 6 anni | C12: ='BP_Seainnova 2027_2032'!M12/1000000 | D12: M€
B13: EBITDA Totale (con PUCk) | C13: ='BP_Seainnova 2027_2032'!T12/1000000 | D13: M€
B14: Anno | C14: Boe Nuove | D14: Boe Totali | E14: Ricavi (€) | F14: EBITDA (€) | G14: Margine %
B15: ='BP_Seainnova 2027_2032'!A6 | C15: ='BP_Seainnova 2027_2032'!B6 | D15: ='BP_Seainnova 2027_2032'!C6 | E15: ='BP_Seainnova 2027_2032'!H6 | F15: ='BP_Seainnova 2027_2032'!L6 | G15: =IF('BP_Seainnova 2027_2032'!H6=0,0,'BP_Seainnova 2027_2032'!L6/'BP_Seainnova 2027_2032'!H6)
B16: ='BP_Seainnova 2027_2032'!A7 | C16: ='BP_Seainnova 2027_2032'!B7 | D16: ='BP_Seainnova 2027_2032'!C7 | E16: ='BP_Seainnova 2027_2032'!H7 | F16: ='BP_Seainnova 2027_2032'!L7 | G16: =IF('BP_Seainnova 2027_2032'!H7=0,0,'BP_Seainnova 2027_2032'!L7/'BP_Seainnova 2027_2032'!H7)
B17: ='BP_Seainnova 2027_2032'!A8 | C17: ='BP_Seainnova 2027_2032'!B8 | D17: ='BP_Seainnova 2027_2032'!C8 | E17: ='BP_Seainnova 2027_2032'!H8 | F17: ='BP_Seainnova 2027_2032'!L8 | G17: =IF('BP_Seainnova 2027_2032'!H8=0,0,'BP_Seainnova 2027_2032'!L8/'BP_Seainnova 2027_2032'!H8)
B18: ='BP_Seainnova 2027_2032'!A9 | C18: ='BP_Seainnova 2027_2032'!B9 | D18: ='BP_Seainnova 2027_2032'!C9 | E18: ='BP_Seainnova 2027_2032'!H9 | F18: ='BP_Seainnova 2027_2032'!L9 | G18: =IF('BP_Seainnova 2027_2032'!H9=0,0,'BP_Seainnova 2027_2032'!L9/'BP_Seainnova 2027_2032'!H9)
B19: ='BP_Seainnova 2027_2032'!A10 | C19: ='BP_Seainnova 2027_2032'!B10 | D19: ='BP_Seainnova 2027_2032'!C10 | E19: ='BP_Seainnova 2027_2032'!H10 | F19: ='BP_Seainnova 2027_2032'!L10 | G19: =IF('BP_Seainnova 2027_2032'!H10=0,0,'BP_Seainnova 2027_2032'!L10/'BP_Seainnova 2027_2032'!H10)
B20: ='BP_Seainnova 2027_2032'!A11 | C20: ='BP_Seainnova 2027_2032'!B11 | D20: ='BP_Seainnova 2027_2032'!C11 | E20: ='BP_Seainnova 2027_2032'!H11 | F20: ='BP_Seainnova 2027_2032'!L11 | G20: =IF('BP_Seainnova 2027_2032'!H11=0,0,'BP_Seainnova 2027_2032'!L11/'BP_Seainnova 2027_2032'!H11)

Sheet Piano_Finanziario
B2: PIANO FINANZIARIO CON CONTRIBUTI
B3: Riepilogo fabbisogno finanziario considerando contributi a fondo perduto
B5: Anno | C5: CAPEX Totale | D5: Contributi FP | E5: Finanziamenti Agev. | F5: CAPEX Netto | G5: OPEX Totale (Boe + PUCK) | H5: Ricavi Totali (Boe + PUCK) | I5: Cash Flow Operativo | J5: Cash Flow Netto
B6: 2027 | C6: ='BP_Seainnova 2027_2032'!S6 | D6: =Assunzioni!C77 | E6: 0 | F6: =C6-D6-E6 | G6: ='BP_Seainnova 2027_2032'!R6 | H6: ='BP_Seainnova 2027_2032'!Q6 | I6: ='BP_Seainnova 2027_2032'!T6-C6 | J6: =I6+D6+E6
B7: 2028 | C7: ='BP_Seainnova 2027_2032'!S7 | D7: 0 | E7: 0 | F7: =C7-D7-E7 | G7: ='BP_Seainnova 2027_2032'!R7 | H7: ='BP_Seainnova 2027_2032'!Q7 | I7: ='BP_Seainnova 2027_2032'!T7-C7 | J7: =I7+D7+E7
B8: 2029 | C8: ='BP_Seainnova 2027_2032'!S8 | D8: 0 | E8: 0 | F8: =C8-D8-E8 | G8: ='BP_Seainnova 2027_2032'!R8 | H8: ='BP_Seainnova 2027_2032'!Q8 | I8: ='BP_Seainnova 2027_2032'!T8-C8 | J8: =I8+D8+E8
B9: 2030 | C9: ='BP_Seainnova 2027_2032'!S9 | D9: 0 | E9: 0 | F9: =C9-D9-E9 | G9: ='BP_Seainnova 2027_2032'!R9 | H9: ='BP_Seainnova 2027_2032'!Q9 | I9: ='BP_Seainnova 2027_2032'!T9-C9 | J9: =I9+D9+E9
B10: 2031 | C10: ='BP_Seainnova 2027_2032'!S10 | D10: 0 | E10: 0 | F10: =C10-D10-E10 | G10: ='BP_Seainnova 2027_2032'!R10 | H10: ='BP_Seainnova 2027_2032'!Q10 | I10: ='BP_Seainnova 2027_2032'!T10-C10 | J10: =I10+D10+E10
B11: 2032 | C11: ='BP_Seainnova 2027_2032'!S11 | D11: 0 | E11: 0 | F11: =C11-D11-E11 | G11: ='BP_Seainnova 2027_2032'!R11 | H11: ='BP_Seainnova 2027_2032'!Q11 | I11: ='BP_Seainnova 2027_2032'!T11-C11 | J11: =I11+D11+E11
B12: TOTALE | C12: =SUM(C6:C11) | D12: =SUM(D6:D11) | E12: =SUM(E6:E11) | F12: =SUM(F6:F11) | G12: =SUM(G6:G11) | H12: =SUM(H6:H11) | I12: =SUM(I6:I11) | J12: =SUM(J6:J11)
B15: 📋 LEGENDA (consolidato Boe + PUCK B2B):
B16: Cash Flow Operativo: | C16: EBITDA TOTALE (Ricavi tot - OPEX tot, include NaviGoo24/PUCK B2B) - CAPEX Totale
B17: Contributi FP: | C17: Contributi a fondo perduto (es. PNRR 80%, ZES Sardegna)
B18: Finanziamenti Agev.: | C18: Prestiti con tassi agevolati (se disponibili)
B19: CAPEX Netto: | C19: Capitale da investire effettivamente (dopo contributi)
B20: Cash Flow Netto: | C20: CF Operativo + Contributi a fondo perduto + Finanziamenti agevolati

Sheet Conto_Economico
B2: CONTO ECONOMICO DETTAGLIATO
B3: 📊 Calcolato automaticamente
C4: Voce | D4: 2027 | E4: 2028 | F4: 2029 | G4: 2030 | H4: 2031 | I4: 2032 | J4: TOTALE
B6: RICAVI
B7: Tariffe ormeggio | C7: ='BP_Seainnova 2027_2032'!H6 | D7: ='BP_Seainnova 2027_2032'!H7 | E7: ='BP_Seainnova 2027_2032'!H8 | F7: ='BP_Seainnova 2027_2032'!H9 | G7: ='BP_Seainnova 2027_2032'!H10 | H7: ='BP_Seainnova 2027_2032'!H11 | I7: =SUM(C7:H7)
B8: Ricavi NaviGoo24 / PUCK B2B | C8: ='BP_Seainnova 2027_2032'!N6 | D8: ='BP_Seainnova 2027_2032'!N7 | E8: ='BP_Seainnova 2027_2032'!N8 | F8: ='BP_Seainnova 2027_2032'!N9 | G8: ='BP_Seainnova 2027_2032'!N10 | H8: ='BP_Seainnova 2027_2032'!N11 | I8: =SUM(C8:H8)
B9: TOTALE RICAVI | C9: ='BP_Seainnova 2027_2032'!Q6 | D9: ='BP_Seainnova 2027_2032'!Q7 | E9: ='BP_Seainnova 2027_2032'!Q8 | F9: ='BP_Seainnova 2027_2032'!Q9 | G9: ='BP_Seainnova 2027_2032'!Q10 | H9: ='BP_Seainnova 2027_2032'!Q11 | I9: =SUM(C9:H9)
B11: CAPEX BOE (non nel CE, a titolo informativo)
B12: Acquisto boe (capitalizzato) | C12: ='BP_Seainnova 2027_2032'!I6 | D12: ='BP_Seainnova 2027_2032'!I7 | E12: ='BP_Seainnova 2027_2032'!I8 | F12: ='BP_Seainnova 2027_2032'!I9 | G12: ='BP_Seainnova 2027_2032'!I10 | H12: ='BP_Seainnova 2027_2032'!I11 | I12: =SUM(C12:H12)
B14: OPEX
B15: OPEX Boe (ricorrenti + struttura) | C15: ='BP_Seainnova 2027_2032'!J6 | D15: ='BP_Seainnova 2027_2032'!J7 | E15: ='BP_Seainnova 2027_2032'!J8 | F15: ='BP_Seainnova 2027_2032'!J9 | G15: ='BP_Seainnova 2027_2032'!J10 | H15: ='BP_Seainnova 2027_2032'!J11 | I15: =SUM(C15:H15)
B16: OPEX NaviGoo24 / PUCK B2B | C16: ='BP_Seainnova 2027_2032'!O6 | D16: ='BP_Seainnova 2027_2032'!O7 | E16: ='BP_Seainnova 2027_2032'!O8 | F16: ='BP_Seainnova 2027_2032'!O9 | G16: ='BP_Seainnova 2027_2032'!O10 | H16: ='BP_Seainnova 2027_2032'!O11 | I16: =SUM(C16:H16)
B17: TOTALE OPEX | C17: ='BP_Seainnova 2027_2032'!R6 | D17: ='BP_Seainnova 2027_2032'!R7 | E17: ='BP_Seainnova 2027_2032'!R8 | F17: ='BP_Seainnova 2027_2032'!R9 | G17: ='BP_Seainnova 2027_2032'!R10 | H17: ='BP_Seainnova 2027_2032'!R11 | I17: =SUM(C17:H17)
B19: EBITDA
B20: EBITDA TOTALE (Ricavi tot - OPEX tot) | C20: ='BP_Seainnova 2027_2032'!T6 | D20: ='BP_Seainnova 2027_2032'!T7 | E20: ='BP_Seainnova 2027_2032'!T8 | F20: ='BP_Seainnova 2027_2032'!T9 | G20: ='BP_Seainnova 2027_2032'!T10 | H20: ='BP_Seainnova 2027_2032'!T11 | I20: =SUM(C20:H20)
B21: Margine % | C21: =IF(C9=0,0,C20/C9) | D21: =IF(D9=0,0,D20/D9) | E21: =IF(E9=0,0,E20/E9) | F21: =IF(F9=0,0,F20/F9) | G21: =IF(G9=0,0,G20/G9) | H21: =IF(H9=0,0,H20/H9) | I21: =IF(I9=0,0,I20/I9)
B22: Ammortamenti | C22: ='BP_Seainnova 2027_2032'!K6 | D22: ='BP_Seainnova 2027_2032'!K7 | E22: ='BP_Seainnova 2027_2032'!K8 | F22: ='BP_Seainnova 2027_2032'!K9 | G22: ='BP_Seainnova 2027_2032'!K10 | H22: ='BP_Seainnova 2027_2032'!K11 | I22: =SUM(C22:H22)
B23: EBIT | C23: =C20-C22 | D23: =D20-D22 | E23: =E20-E22 | F23: =F20-F22 | G23: =G20-G22 | H23: =H20-H22 | I23: =SUM(C23:H23)
B25: CASH FLOW OPERATIVO
B26: Cash Flow Operativo (EBITDA Tot - CAPEX Tot) | C26: ='BP_Seainnova 2027_2032'!T6-'BP_Seainnova 2027_2032'!S6 | D26: ='BP_Seainnova 2027_2032'!T7-'BP_Seainnova 2027_2032'!S7 | E26: ='BP_Seainnova 2027_2032'!T8-'BP_Seainnova 2027_2032'!S8 | F26: ='BP_Seainnova 2027_2032'!T9-'BP_Seainnova 2027_2032'!S9 | G26: ='BP_Seainnova 2027_2032'!T10-'BP_Seainnova 2027_2032'!S10 | H26: ='BP_Seainnova 2027_2032'!T11-'BP_Seainnova 2027_2032'!S11 | I26: =SUM(C26:H26)

Sheet Glossario
B2: GLOSSARIO E DEFINIZIONI
B4: Termine | C4: Definizione
B5: Boa da ormeggio | C5: Sistema fisico per ancoraggio imbarcazioni, composto da boa galleggiante, catena e corpo morto
B6: Corpo vivo | C6: Elemento in granito eco-compatibile sul fondale che favorisce biodiversità marina
B7: Occupancy | C7: Percentuale di utilizzo effettivo della boa rispetto ai giorni operativi disponibili
B8: PUCK App | C8: Applicazione mobile Seainnova per prenotazione, pagamento e gestione ormeggi
B9: Tariffa uso | C9: Costo per singolo ormeggio/utilizzo della boa
B10: OPEX | C10: Operating Expenses - Costi operativi ricorrenti
B11: CAPEX | C11: Capital Expenditure - Investimenti in asset
B12: EBITDA | C12: Earnings Before Interest, Taxes, Depreciation, Amortization
B13: Break-even | C13: Punto di pareggio dove ricavi = costi totali
B14: AMP | C14: Area Marina Protetta
B15: PNRR | C15: Piano Nazionale Ripresa e Resilienza
B16: ZES | C16: Zona Economica Speciale - Sardegna

Sheet NaviGoo24 B2B Detail
A1: PUCK B2B - BREAKDOWN DETTAGLIATO
A2: Scenario B Ottimizzato - VALORI DINAMICI da foglio Assunzioni
A4: Anno | B4: Contratti Totali | C4: Penetr. Mercato % | D4: N° Basic | E4: N° Premium | F4: N° Enterprise | G4: % Basic | H4: % Premium | I4: % Enterprise | J4: Ricavi Basic € | K4: Ricavi Premium € | L4: Ricavi Enterprise € | M4: TOTALE RICAVI € | N4: OPEX SW € | O4: OPEX Marketing € | P4: OPEX Infrastr. € | Q4: OPEX Vendita € | R4: TOTALE OPEX € | S4: EBITDA € | T4: Margine %
A5: 2027 | B5: =Assunzioni!C129 | C5: =B5/1020 | D5: =Assunzioni!D129 | E5: =Assunzioni!E129 | F5: =Assunzioni!F129 | G5: =D5/B5 | H5: =E5/B5 | I5: =F5/B5 | J5: =D5*Assunzioni!$C$123*12 | K5: =E5*Assunzioni!$C$124*12 | L5: =F5*Assunzioni!$C$125*12 | M5: =J5+K5+L5 | N5: =Assunzioni!C137 | O5: =Assunzioni!D137 | P5: =Assunzioni!E137 | Q5: =Assunzioni!F137 | R5: =N5+O5+P5+Q5 | S5: =M5-R5 | T5: =IF(M5>0,S5/M5,0)
A6: 2028 | B6: =Assunzioni!C130 | C6: =B6/1020 | D6: =Assunzioni!D130 | E6: =Assunzioni!E130 | F6: =Assunzioni!F130 | G6: =D6/B6 | H6: =E6/B6 | I6: =F6/B6 | J6: =D6*Assunzioni!$C$123*12 | K6: =E6*Assunzioni!$C$124*12 | L6: =F6*Assunzioni!$C$125*12 | M6: =J6+K6+L6 | N6: =Assunzioni!C138 | O6: =Assunzioni!D138 | P6: =Assunzioni!E138 | Q6: =Assunzioni!F138 | R6: =N6+O6+P6+Q6 | S6: =M6-R6 | T6: =IF(M6>0,S6/M6,0)
A7: 2029 | B7: =Assunzioni!C131 | C7: =B7/1020 | D7: =Assunzioni!D131 | E7: =Assunzioni!E131 | F7: =Assunzioni!F131 | G7: =D7/B7 | H7: =E7/B7 | I7: =F7/B7 | J7: =D7*Assunzioni!$C$123*12 | K7: =E7*Assunzioni!$C$124*12 | L7: =F7*Assunzioni!$C$125*12 | M7: =J7+K7+L7 | N7: =Assunzioni!C139 | O7: =Assunzioni!D139 | P7: =Assunzioni!E139 | Q7: =Assunzioni!F139 | R7: =N7+O7+P7+Q7 | S7: =M7-R7 | T7: =IF(M7>0,S7/M7,0)
A8: 2030 | B8: =Assunzioni!C132 | C8: =B8/1020 | D8: =Assunzioni!D132 | E8: =Assunzioni!E132 | F8: =Assunzioni!F132 | G8: =D8/B8 | H8: =E8/B8 | I8: =F8/B8 | J8: =D8*Assunzioni!$C$123*12 | K8: =E8*Assunzioni!$C$124*12 | L8: =F8*Assunzioni!$C$125*12 | M8: =J8+K8+L8 | N8: =Assunzioni!C140 | O8: =Assunzioni!D140 | P8: =Assunzioni!E140 | Q8: =Assunzioni!F140 | R8: =N8+O8+P8+Q8 | S8: =M8-R8 | T8: =IF(M8>0,S8/M8,0)
A9: 2031 | B9: =Assunzioni!C133 | C9: =B9/1020 | D9: =Assunzioni!D133 | E9: =Assunzioni!E133 | F9: =Assunzioni!F133 | G9: =D9/B9 | H9: =E9/B9 | I9: =F9/B9 | J9: =D9*Assunzioni!$C$123*12 | K9: =E9*Assunzioni!$C$124*12 | L9: =F9*Assunzioni!$C$125*12 | M9: =J9+K9+L9 | N9: =Assunzioni!C141 | O9: =Assunzioni!D141 | P9: =Assunzioni!E141 | Q9: =Assunzioni!F141 | R9: =N9+O9+P9+Q9 | S9: =M9-R9 | T9: =IF(M9>0,S9/M9,0)
A10: 2032 | B10: =Assunzioni!C134 | C10: =B10/1020 | D10: =Assunzioni!D134 | E10: =Assunzioni!E134 | F10: =Assunzioni!F134 | G10: =D10/B10 | H10: =E10/B10 | I10: =F10/B10 | J10: =D10*Assunzioni!$C$123*12 | K10: =E10*Assunzioni!$C$124*12 | L10: =F10*Assunzioni!$C$125*12 | M10: =J10+K10+L10 | N10: =Assunzioni!C142 | O10: =Assunzioni!D142 | P10: =Assunzioni!E142 | Q10: =Assunzioni!F142 | R10: =N10+O10+P10+Q10 | S10: =M10-R10 | T10: =IF(M10>0,S10/M10,0)
A11: TOTALE 6 ANNI | B11: =SUM(B5:B10) | D11: =SUM(D5:D10) | E11: =SUM(E5:E10) | F11: =SUM(F5:F10) | J11: =SUM(J5:J10) | K11: =SUM(K5:K10) | L11: =SUM(L5:L10) | M11: =SUM(M5:M10) | N11: =SUM(N5:N10) | O11: =SUM(O5:O10) | P11: =SUM(P5:P10) | Q11: =SUM(Q5:Q10) | ... S11: =SUM(S5:S10) | T11: =S11/M11

Sheet Grafici NaviGoo24
A1: GRAFICI PUCK B2B

Sheet ANALISI BEP
B1: TORNA ALL'INDICE
B2: ANALISI DI RESILIENZA E BREAK-EVEN POINT
B4: Anno | C4: Boe Effettive | D4: BEP Scenario Base (Boe) | E4: BEP +15% Costi Fissi (Boe) | F4: BEP +10% Costi Var (Boe) | G4: Margine Sicurezza (%)
B5: 2027 | C5: 15 | D5: =(Assunzioni!$C$27*(1+Assunzioni!$C$28/100)^0)/('BP_Seainnova 2027_2032'!H6/'BP_Seainnova 2027_2032'!C6-Assunzioni!$C$46) | E5: =(Assunzioni!$C$27*(1+Assunzioni!$C$28/100)^0*1.15)/('BP_Seainnova 2027_2032'!H6/'BP_Seainnova 2027_2032'!C6-Assunzioni!$C$46) | F5: =(Assunzioni!$C$27*(1+Assunzioni!$C$28/100)^0)/('BP_Seainnova 2027_2032'!H6/'BP_Seainnova 2027_2032'!C6-Assunzioni!$C$46*1.1) | G5: =(C5-D5)/C5
B6: 2028 | C6: 75 | D6: =(Assunzioni!$C$27*(1+Assunzioni!$C$28/100)^1)/('BP_Seainnova 2027_2032'!H7/'BP_Seainnova 2027_2032'!C7-Assunzioni!$C$46) | E6: =(Assunzioni!$C$27*(1+Assunzioni!$C$28/100)^1*1.15)/('BP_Seainnova 2027_2032'!H7/'BP_Seainnova 2027_2032'!C7-Assunzioni!$C$46) | F6: =(Assunzioni!$C$27*(1+Assunzioni!$C$28/100)^1)/('BP_Seainnova 2027_2032'!H7/'BP_Seainnova 2027_2032'!C7-Assunzioni!$C$46*1.1) | G6: =(C6-D6)/C6
B7: 2029 | C7: 175 | D7: =(Assunzioni!$C$27*(1+Assunzioni!$C$28/100)^2)/('BP_Seainnova 2027_2032'!H8/'BP_Seainnova 2027_2032'!C8-Assunzioni!$C$46) | E7: =(Assunzioni!$C$27*(1+Assunzioni!$C$28/100)^2*1.15)/('BP_Seainnova 2027_2032'!H8/'BP_Seainnova 2027_2032'!C8-Assunzioni!$C$46) | F7: =(Assunzioni!$C$27*(1+Assunzioni!$C$28/100)^2)/('BP_Seainnova 2027_2032'!H8/'BP_Seainnova 2027_2032'!C8-Assunzioni!$C$46*1.1) | G7: =(C7-D7)/C7
B8: 2030 | C8: 315 | D8: =(Assunzioni!$C$27*(1+Assunzioni!$C$28/100)^3)/('BP_Seainnova 2027_2032'!H9/'BP_Seainnova 2027_2032'!C9-Assunzioni!$C$46) | E8: =(Assunzioni!$C$27*(1+Assunzioni!$C$28/100)^3*1.15)/('BP_Seainnova 2027_2032'!H9/'BP_Seainnova 2027_2032'!C9-Assunzioni!$C$46) | F8: =(Assunzioni!$C$27*(1+Assunzioni!$C$28/100)^3)/('BP_Seainnova 2027_2032'!H9/'BP_Seainnova 2027_2032'!C9-Assunzioni!$C$46*1.1) | G8: =(C8-D8)/C8
B9: 2031 | C9: 495 | D9: =(Assunzioni!$C$27*(1+Assunzioni!$C$28/100)^4)/('BP_Seainnova 2027_2032'!H10/'BP_Seainnova 2027_2032'!C10-Assunzioni!$C$46) | E9: =(Assunzioni!$C$27*(1+Assunzioni!$C$28/100)^4*1.15)/('BP_Seainnova 2027_2032'!H10/'BP_Seainnova 2027_2032'!C10-Assunzioni!$C$46) | F9: =(Assunzioni!$C$27*(1+Assunzioni!$C$28/100)^4)/('BP_Seainnova 2027_2032'!H10/'BP_Seainnova 2027_2032'!C10-Assunzioni!$C$46*1.1) | G9: =(C9-D9)/C9
B10: 2032 | C10: 715 | D10: =(Assunzioni!$C$27*(1+Assunzioni!$C$28/100)^5)/('BP_Seainnova 2027_2032'!H11/'BP_Seainnova 2027_2032'!C11-Assunzioni!$C$46) | E10: =(Assunzioni!$C$27*(1+Assunzioni!$C$28/100)^5*1.15)/('BP_Seainnova 2027_2032'!H11/'BP_Seainnova 2027_2032'!C11-Assunzioni!$C$46) | F10: =(Assunzioni!$C$27*(1+Assunzioni!$C$28/100)^5)/('BP_Seainnova 2027_2032'!H11/'BP_Seainnova 2027_2032'!C11-Assunzioni!$C$46*1.1) | G10: =(C10-D10)/C10

Sheet COERENZA_FLUSSI
B1: MATRICE DI COERENZA DEI FLUSSI
B2: Ricalcolo indipendente dalle Assunzioni vs formule del BP
B4: RICALCOLO INDIPENDENTE (dalle Assunzioni) vs RISULTATI BP
B5: Anno | C5: Controllo | D5: Ricalcolo | E5: Valore BP | F5: Esito
B6: 2027 | C6: Ricavi | D6: =SUM(Assunzioni!C8:C8)*(Assunzioni!D17/100)*Assunzioni!E17*Assunzioni!C17 | E6: ='BP_Seainnova 2027_2032'!H6 | F6: =IF(ABS(D6-E6)<1,"OK","ERRORE")
C7: OPEX | D7: =Assunzioni!$C$27*(1+Assunzioni!$C$28/100)^0+Assunzioni!$C$46*SUM(Assunzioni!C8:C8) | E7: ='BP_Seainnova 2027_2032'!J6 | F7: =IF(ABS(D7-E7)<1,"OK","ERRORE")
C8: CAPEX Boe | D8: =Assunzioni!C8*Assunzioni!$C$26*(1-Assunzioni!$C$36/100) | E8: ='BP_Seainnova 2027_2032'!I6 | F8: =IF(ABS(D8-E8)<1,"OK","ERRORE")
C9: Ammortamenti | D9: =Assunzioni!D115 | E9: ='BP_Seainnova 2027_2032'!K6 | F9: =IF(ABS(D9-E9)<1,"OK","ERRORE")
C10: EBITDA | D10: =D6-D7 | E10: ='BP_Seainnova 2027_2032'!L6 | F10: =IF(ABS(D10-E10)<1,"OK","ERRORE")
C11: EBIT | D11: =D10-D9 | E11: ='BP_Seainnova 2027_2032'!M6 | F11: =IF(ABS(D11-E11)<1,"OK","ERRORE")
B12: 2028 | C12: Ricavi | D12: =SUM(Assunzioni!C8:C9)*(Assunzioni!D18/100)*Assunzioni!E18*Assunzioni!C18 | E12: ='BP_Seainnova 2027_2032'!H7 | F12: =IF(ABS(D12-E12)<1,"OK","ERRORE")
C13: OPEX | D13: =Assunzioni!$C$27*(1+Assunzioni!$C$28/100)^1+Assunzioni!$C$46*SUM(Assunzioni!C8:C9) | E13: ='BP_Seainnova 2027_2032'!J7 | F13: =IF(ABS(D13-E13)<1,"OK","ERRORE")
C14: CAPEX Boe | D14: =Assunzioni!C9*Assunzioni!$C$26*(1-Assunzioni!$C$36/100) | E14: ='BP_Seainnova 2027_2032'!I7 | F14: =IF(ABS(D14-E14)<1,"OK","ERRORE")
C15: Ammortamenti | D15: =Assunzioni!E115 | E15: ='BP_Seainnova 2027_2032'!K7 | F15: =IF(ABS(D15-E15)<1,"OK","ERRORE")
C16: EBITDA | D16: =D12-D13 | E16: ='BP_Seainnova 2027_2032'!L7 | F16: =IF(ABS(D16-E16)<1,"OK","ERRORE")
C17: EBIT | D17: =D16-D15 | E17: ='BP_Seainnova 2027_2032'!M7 | F17: =IF(ABS(D17-E17)<1,"OK","ERRORE")
B18: 2029 | C18: Ricavi | D18: =SUM(Assunzioni!C8:C10)*(Assunzioni!D19/100)*Assunzioni!E19*Assunzioni!C19 | E18: ='BP_Seainnova 2027_2032'!H8 | F18: =IF(ABS(D18-E18)<1,"OK","ERRORE")
C19: OPEX | D19: =Assunzioni!$C$27*(1+Assunzioni!$C$28/100)^2+Assunzioni!$C$46*SUM(Assunzioni!C8:C10) | E19: ='BP_Seainnova 2027_2032'!J8 | F19: =IF(ABS(D19-E19)<1,"OK","ERRORE")
C20: CAPEX Boe | D20: =Assunzioni!C10*Assunzioni!$C$26*(1-Assunzioni!$C$36/100) | E20: ='BP_Seainnova 2027_2032'!I8 | F20: =IF(ABS(D20-E20)<1,"OK","ERRORE")
C21: Ammortamenti | D21: =Assunzioni!F115 | E21: ='BP_Seainnova 2027_2032'!K8 | F21: =IF(ABS(D21-E21)<1,"OK","ERRORE")
C22: EBITDA | D22: =D18-D19 | E22: ='BP_Seainnova 2027_2032'!L8 | F22: =IF(ABS(D22-E22)<1,"OK","ERRORE")
C23: EBIT | D23: =D22-D21 | E23: ='BP_Seainnova 2027_2032'!M8 | F23: =IF(ABS(D23-E23)<1,"OK","ERRORE")
B24: 2030 | C24: Ricavi | D24: =SUM(Assunzioni!C8:C11)*(Assunzioni!D20/100)*Assunzioni!E20*Assunzioni!C20 | E24: ='BP_Seainnova 2027_2032'!H9 | F24: =IF(ABS(D24-E24)<1,"OK","ERRORE")
C25: OPEX | D25: =Assunzioni!$C$27*(1+Assunzioni!$C$28/100)^3+Assunzioni!$C$46*SUM(Assunzioni!C8:C11) | E25: ='BP_Seainnova 2027_2032'!J9 | F25: =IF(ABS(D25-E25)<1,"OK","ERRORE")
C26: CAPEX Boe | D26: =Assunzioni!C11*Assunzioni!$C$26*(1-Assunzioni!$C$36/100) | E26: ='BP_Seainnova 2027_2032'!I9 | F26: =IF(ABS(D26-E26)<1,"OK","ERRORE")
C27: Ammortamenti | D27: =Assunzioni!G115 | E27: ='BP_Seainnova 2027_2032'!K9 | F27: =IF(ABS(D27-E27)<1,"OK","ERRORE")
C28: EBITDA | D28: =D24-D25 | E28: ='BP_Seainnova 2027_2032'!L9 | F28: =IF(ABS(D28-E28)<1,"OK","ERRORE")
C29: EBIT | D29: =D28-D27 | E29: ='BP_Seainnova 2027_2032'!M9 | F29: =IF(ABS(D29-E29)<1,"OK","ERRORE")
B30: 2031 | C30: Ricavi | D30: =SUM(Assunzioni!C8:C12)*(Assunzioni!D21/100)*Assunzioni!E21*Assunzioni!C21 | E30: ='BP_Seainnova 2027_2032'!H10 | F30: =IF(ABS(D30-E30)<1,"OK","ERRORE")
C31: OPEX | D31: =Assunzioni!$C$27*(1+Assunzioni!$C$28/100)^4+Assunzioni!$C$46*SUM(Assunzioni!C8:C12) | E31: ='BP_Seainnova 2027_2032'!J10 | F31: =IF(ABS(D31-E31)<1,"OK","ERRORE")
C32: CAPEX Boe | D32: =Assunzioni!C12*Assunzioni!$C$26*(1-Assunzioni!$C$36/100) | E32: ='BP_Seainnova 2027_2032'!I10 | F32: =IF(ABS(D32-E32)<1,"OK","ERRORE")
C33: Ammortamenti | D33: =Assunzioni!H115 | E33: ='BP_Seainnova 2027_2032'!K10 | F33: =IF(ABS(D33-E33)<1,"OK","ERRORE")
C34: EBITDA | D34: =D30-D31 | E34: ='BP_Seainnova 2027_2032'!L10 | F34: =IF(ABS(D34-E34)<1,"OK","ERRORE")
C35: EBIT | D35: =D34-D33 | E35: ='BP_Seainnova 2027_2032'!M10 | F35: =IF(ABS(D35-E35)<1,"OK","ERRORE")
B36: 2032 | C36: Ricavi | D36: =SUM(Assunzioni!C8:C13)*(Assunzioni!D22/100)*Assunzioni!E22*Assunzioni!C22 | E36: ='BP_Seainnova 2027_2032'!H11 | F36: =IF(ABS(D36-E36)<1,"OK","ERRORE")
C37: OPEX | D37: =Assunzioni!$C$27*(1+Assunzioni!$C$28/100)^5+Assunzioni!$C$46*SUM(Assunzioni!C8:C13) | E37: ='BP_Seainnova 2027_2032'!J11 | F37: =IF(ABS(D37-E37)<1,"OK","ERRORE")
C38: CAPEX Boe | D38: =Assunzioni!C13*Assunzioni!$C$26*(1-Assunzioni!$C$36/100) | E38: ='BP_Seainnova 2027_2032'!I11 | F38: =IF(ABS(D38-E38)<1,"OK","ERRORE")
C39: Ammortamenti | D39: =Assunzioni!I115 | E39: ='BP_Seainnova 2027_2032'!K11 | F39: =IF(ABS(D39-E39)<1,"OK","ERRORE")
C40: EBITDA | D40: =D36-D37 | E40: ='BP_Seainnova 2027_2032'!L11 | F40: =IF(ABS(D40-E40)<1,"OK","ERRORE")
C41: EBIT | D41: =D40-D39 | E41: ='BP_Seainnova 2027_2032'!M11 | F41: =IF(ABS(D41-E41)<1,"OK","ERRORE")
...
